Workbook

Sheet README
A1: How to read this workbook
A3: Purpose | B3: Test whether European gas prices drive / predict moves on the German yield curve through inflation expectations and ECB rate expectations, with focus on the Iran-war regime (from 2 Mar 2026).
A4: Start here | B4: Executive_Summary (results & economic meaning) -> Economic_Intuition (the chain) -> Benchmarks (why these instruments) -> Test_Catalog (every test, one line each) -> Charts.
A5: Result sheets | B5: One sheet per test family, exported from Python. Green fill = p < 0.05 (in Diagnostics: a problem detected).
A6: Units | B6: Rates: bp. Prices: % log change. 'bp_per_10pct_ttf' = bp move for a +10% TTF move.
A7: Colour code | B7: Green text = live formula linking to another sheet. Black = values/text. Formulas in Event_Study compute changes from levels.
A8: Reproduce | B8: .venv/bin/python src/clean.py && .venv/bin/python src/econometrics.py && .venv/bin/python src/figures.py && .venv/bin/python src/build_workbook.py
A9: Data | B9: Raw exports archived under canonical names in data/raw/; clean panels in data/clean/.
A10: Prepared | B10: 11 Oct 2026, data to 9 Oct 2026 close.

Sheet Executive_Summary
A1: Gas -> Inflation Expectations -> ECB Pricing -> Bund Curve: Results Recap
A2: Sample: daily Oct 2014 - 9 Oct 2026 (€STR OIS from Oct 2019, 1Y ILS from Apr 2022). Iran-war regime from 2 Mar 2026 (143 trading days / 32 weeks). Green numbers link live to the result sheets.
A4: Link in the chain | B4: Metric | C4: Estimate | D4: p-value | E4: Verdict | F4: Economic meaning
A5: 1. Gas -> realised inflation | B5: HICP y/y per +10% TTF, 9 months later (pp) | C5: ='HICP_Passthrough'!$E$30 | D5: ='HICP_Passthrough'!$D$30 | E5: SUPPORTED, WITH A LAG | F5: Gas reaches consumer prices through retail gas/electricity tariffs that reset slowly; the effect is ~0 on impact and builds to ~0.2pp of y/y HICP per +10% after 9-12 months. Oil, by contrast, passes through immediately. Gas is therefore a LEADING indicator of headline inflation at exactly the 1-year horizon the ECB targets.
A6: 1b. ... vs oil (benchmark) | B6: HICP y/y per +10% Brent, same month (pp) | C6: ='HICP_Passthrough'!$H$21 | D6: ='HICP_Passthrough'!$G$21 | E6: CONTEXT | F6: Oil is the faster, larger inflation driver; any 'gas' result must control for Brent (all regressions do).
A7: 2. Gas -> market inflation expectations | B7: Infl. swap 1Y, bp per +10% TTF, war regime | C7: ='Transmission_Daily'!$F$9 | D7: ='Transmission_Daily'!$H$9 | E7: SUPPORTED, AMPLIFIED IN WAR | F7: Inflation swaps reprice the same day. Sensitivity in the war (~7bp per +10%) is ~4x the 2023-26 level. The 1y1y forward moves much less (~1.8bp) and reverses within ~20 trading days (local projections, short sample): markets treat most of the gas spike as a near-term price-level shock rather than persistent inflation.
A8: 2b. ... forward expectations | B8: Infl. swap 1y1y, bp per +10% TTF, war regime | C8: ='Transmission_Daily'!$F$14 | D8: ='Transmission_Daily'!$H$14 | E8: SUPPORTED (WEAKER) | F8: The forward the ECB cares about responds, but modestly, and Brent explains more of it than gas.
A9: 3. Expectations -> ECB rate pricing | B9: €STR OIS 1y1y, bp per +10% TTF, war regime (weekly) | C9: ='Transmission_Weekly'!$E$23 | D9: ='Transmission_Weekly'!$G$23 | E9: SUPPORTED | F9: Gas moves the expected policy path in the war (~2.3bp daily, ~4.8bp weekly per +10%). About a third of the daily effect runs through inflation swaps; the rest is priced directly - the market reads energy headlines straight into the ECB reaction function. A break test dates the shift to early March 2026 without being told the war date.
A10: 3b. Break in policy sensitivity | B10: sup-Wald stat, €STR OIS 2Y (5% cv = 8.68) | C10: ='Structural_Breaks'!$H$13 | D10: ='Structural_Breaks'!$G$13 | E10: CONFIRMED (1%) | F10: The estimated break date is in the first week of the war (see Structural_Breaks).
A11: 4. Policy pricing -> Bund front end | B11: Bund 2Y, bp per +10% TTF, war regime (daily; Holm-corrected p within the rates family) | C11: ='Transmission_Daily'!$F$34 | D11: ='Transmission_Daily'!$J$34 | E11: SUPPORTED | F11: A +10% gas day lifts the Schatz ~4bp in the war (raw p = 0.003; weekly: ~3.6bp, p = 0.001). After Holm correction it stays significant within the 13 rate series (p = 0.036) and is borderline across all 20 series tested (p = 0.057). Weekly mediation: OIS 1y1y passes ~0.7bp per bp into the 2Y Bund.
A12: 4b. Curve shape | B12: Slope 2s30s, bp per +10% TTF, war regime (daily) | C12: ='Transmission_Daily'!$F$84 | D12: ='Transmission_Daily'!$H$84 | E12: SUPPORTED: BEAR FLATTENING | F12: The 30Y barely moves (~0.2bp) while the front end rises: gas shocks are priced as POLICY shocks, not as term-premium or long-run inflation shocks. Confirmed by the PCA slope factor and by weekly 5s30s (-2.6bp, p < 0.001).
A13: 4c. Which flattener | B13: Slope 2s30s, weekly, bp per +10% TTF, war | C13: ='Curve_Slopes'!$J$11 | D13: ='Curve_Slopes'!$K$11 | E13: 2s30s LARGEST; 2s10s CLEANEST | F13: All six slopes flatten on gas in the war. 2s30s is the largest and is significant daily and weekly, but Brent flattens it too. 2s10s (-2.8bp daily) and 2s5s (-2.1bp daily) respond to gas but not to oil, so they are the purest gas expressions; 2s5s fades within the week. Before 2021 gas slightly STEEPENED the curve (front end pinned at the lower bound).
A14: 5. Regime dependence | B14: Bund 2Y, bp per +10% TTF, 2021-22 gas crisis (daily) | C14: ='Transmission_Daily'!$F$32 | D14: ='Transmission_Daily'!$H$32 | E14: STRONGLY SUPPORTED | F14: In 2021-22 higher gas meant LOWER Bund and OIS rates: markets priced recession risk and an ECB that called inflation transitory. In 2026 the ECB is seen as reactive (it hiked in June and September), so gas is a hawkish signal. The sign of the gas-rates beta is set by the perceived central-bank reaction function, not by gas itself.
A15: 5b. War vs base difference test | B15: Bund 2Y: war minus base effect, bp per +10% | C15: ='Regime_Tests'!$E$15 | D15: ='Regime_Tests'!$G$15 | E15: SIGNIFICANT | F15: Formal test that the war-regime sensitivity differs from normal times.
A16: 6. Predictivity of curve moves | B16: OOS R2, next-week Bund 2Y, gas model vs no-change (war) | C16: ='OOS_Forecast'!$I$34 | D16: ='OOS_Forecast'!$K$34 | E16: NOT SUPPORTED (market frequency) | F16: Gas EXPLAINS same-day curve moves but does not FORECAST later ones: local projections show no drift after day 1-2, Granger tests (weekly) find no lead from TTF to Bunds, and OOS forecasts do not beat a random walk. Only next-week €STR OIS shows a fragile gain in the war (31 forecasts). The predictive channel is macro: gas -> HICP 6-12 months out.
A17: 7. Oil vs gas | B17: Brent effect on €STR OIS 1y1y, bp per +10%, war (daily) | C17: ='Transmission_Daily'!$M$24 | D17: ='Transmission_Daily'!$O$24 | E17: CAVEAT | F17: Brent's effect on inflation and policy pricing is 3-5x gas's. In the Hormuz shock oil and gas co-move (corr ~0.67), so their separate contributions are only partly identified (VAR FEVD: TTF share of OIS 1y1y variance 2% if Brent is ordered first, 40% if TTF is first). The gas effect on the Bund front end survives the Brent control.
A19: Bottom line
A20: • | B20: The thesis holds in the current regime: since 2 March 2026, gas has been a significant driver of euro inflation swaps, of the expected ECB path and of the Bund front end, and it bear-flattens the curve.
A21: • | B21: It is conditional, not structural: before 2021 the link was ~0 and in 2021-22 it had the opposite sign. Any trade or model built on it must monitor the rolling sensitivity (Rolling_Betas / chart f3).
A22: • | B22: Gas explains curve moves contemporaneously; it does not give a tradable lead at daily/weekly frequency. Its genuine predictive content is for realised inflation 6-12 months ahead, i.e. for the data the ECB will react to.
A24: Methodological safeguards applied
A25: • | B25: Model in changes: all levels are I(1) (ADF/KPSS/Zivot-Andrews), no robust cointegration.
A26: • | B26: Newey-West HAC inference everywhere (fat tails, heteroskedasticity, ARCH and serial correlation detected).
A27: • | B27: Front-month roll days removed from TTF/Brent/NBP/HH returns (open-interest based detection).
A28: • | B28: Bundesbank yields are observed ~half a day before LSEG closes: daily Bund regressions include previous-day market moves; full-chain mediation/VAR with Bunds run weekly; predictive tests skip the overlapping day.
A29: • | B29: Brent and EURUSD controls in every regression; Holm correction for multiple testing; block-bootstrap CIs.
A31: Limits
A32: • | B32: One war episode: 143 daily / 32 weekly observations. Estimates are precise enough to reject zero but not to pin down magnitudes tightly.
A33: • | B33: Co-movement conditional on controls is not full causal identification: geopolitical news moves gas, oil and rates together. A cleaner design would instrument gas with LNG-specific outage news or use intraday event windows.
A34: • | B34: RESET flags some non-linearity (large gas days may matter disproportionately) - a threshold model is a natural extension.

Sheet Economic_Intuition
A1: Economic intuition: the transmission chain and how each link is tested
A2: Each row is one link of the thesis: mechanism, expected sign, what would falsify it, the benchmark used, the tests, and the outcome.
A4: # | B4: Link | C4: Mechanism (why) | D4: Expected sign | E4: What would falsify it | F4: Benchmarks used | G4: Tests | H4: Outcome
A5: 1 | B5: Gas price -> realised inflation | C5: Gas sets the marginal price of electricity (merit order) and feeds household gas tariffs, fertiliser, chemicals and industrial costs. Retail tariffs are regulated or contracted and reset with a lag of months. | D5: + (lagged) | E5: No relation between TTF and HICP at any lag once oil is controlled for. | F5: TTF (EUR), HICP y/y and m/m, Brent (EUR) | G5: Distributed-lag regression (13 lags), Granger, y/y lag scan | H5: Supported: ~0 on impact, +0.2pp y/y per +10% after 9-12 months (p <= 0.02). Oil passes through immediately.
A6: 2 | B6: Gas -> market inflation expectations | C6: Forward-looking investors price the future HICP prints today via inflation-linked swaps (HICPxT). The 1Y spot swap captures the near-term price level; the 1y1y forward captures persistence into the ECB's horizon. | D6: + | E6: Inflation swaps do not react to gas once Brent is controlled for. | F6: ILS 1Y (EUCPIZ1Y=TWEB), ILS 1y1y (EUIL1YF1Y=R) | G6: Regime regressions (HAC), interaction Wald, LP, break tests | H6: Supported. ILS 1Y ~+7bp per +10% TTF in the war (p < 0.001); 1y1y ~+1.8bp; Brent dominates both.
A7: 3 | B7: Inflation expectations -> ECB rate expectations | C7: A central bank with a credible inflation-targeting reaction function raises the expected policy path when expected inflation rises, especially if second-round effects or de-anchoring are feared. | D7: + (only if the ECB is seen as reactive) | E7: OIS does not move with gas/ILS, or moves down (growth fears dominate). | F7: €STR OIS 1M/3M/1Y/2Y, OIS 1y1y forward (derived) | G7: Mediation with block bootstrap, VAR/Granger, sup-Wald break | H7: Supported in the war: OIS 1y1y +2.3bp (daily) / +4.8bp (weekly) per +10% TTF; ~1/3 via ILS. Negative in 2021-22.
A8: 4 | B8: ECB expectations -> Bund curve | C8: The 2Y Schatz tracks the expected policy path (plus a scarcity premium); long maturities add term premium and long-run inflation risk. A policy shock lifts the front end more than the long end = bear flattening. | D8: 2Y +, slope - | E8: Long end reacts as much as the front (term-premium shock) or curve steepens. | F8: Bundesbank 2Y-30Y yields, slopes, PCA factors, Bund-OIS spread, 5Y swap spread | G8: Transmission regressions, PCA, weekly mediation | H8: Supported: 2Y ~+4bp, 30Y ~0, 2s30s ~-3.9bp per +10% TTF; PCA slope factor significant.
A9: 5 | B9: Regime dependence | C9: The SIGN of the gas-rates link depends on how markets expect the ECB to react. If gas is read as a growth shock and the ECB as patient (2022 'transitory'), yields fall; if the ECB is seen as reactive (2026 hikes), yields rise. | D9: Varies by regime | E9: Constant beta across regimes. | F9: All of the above | G9: Regime splits, interaction tests, Chow/sup-Wald, rolling betas | H9: Strongly supported: negative in 2021-22, ~0 in normal times, positive in the war.
A10: 6 | B10: Predictivity | C10: Efficient markets should price public gas information immediately, so a tradable lead-lag is not expected. Predictivity is plausible only via slow-moving fundamentals (inflation prints) or limited attention. | D10: None at market frequency; + for macro data | E10: Gas moves today predict curve moves next days/weeks. | F10: Same series | G10: Local projections, Granger, out-of-sample Clark-West tests | H10: Not supported for curve moves (no drift after day 1-2, no OOS gain for Bunds); supported for HICP 6-12m ahead.
A11: C | B11: Confounders | C11: Oil (Hormuz hits both), EUR exchange rate (energy priced in USD), global risk-off (flight to Bund quality), German fiscal supply (long end). | D11: - | E11: - | F11: Brent, EURUSD, 5Y swap spread, Bund-OIS spread | G11: Controls in every regression, VAR orderings, swap-spread regressions | H11: Gas effect on front end survives Brent control; oil and gas effects are only partly separable in the war.
A13: Chain diagram
B14: Hormuz / Qatar LNG supply shock
B15: -> TTF gas price (and Brent)
B16: -> realised HICP (energy, with a 6-12 month lag) [link 1]
B17: -> inflation swaps 1Y / 1y1y (priced immediately) [link 2]
B18: -> €STR OIS 1y1y = expected ECB path [link 3]
B19: -> Bund 2Y up more than Bund 30Y = bear flattening [link 4]

Sheet Benchmarks
A1: Benchmarks used, why these, and what was rejected
A2: Clean variable names as used in data/clean/*.csv. Full definitions: Data_Dictionary sheet.
A4: Role in the chain | B4: Clean name | C4: Instrument / source | D4: Unit | E4: History | F4: Why this benchmark | G4: Alternatives considered | H4: Treatment / caveat
A5: Gas | B5: gas_ttf_m1_eurmwh | C5: ICE Endex Dutch TTF front-month (LSEG TFMBMc1) | D5: EUR/MWh | E5: Oct 2014 - | F5: THE euro-area wholesale gas benchmark; in EUR, so no FX noise; most liquid European gas contract; front month is what headlines and retail tariff indexation track. | G5: NBP (UK hub, GBp/therm - kept for robustness), Henry Hub (US, not a euro-area cost), IMF EU monthly average (monthly, USD, revised). | H5: Continuation contract: roll days removed (OI jump).
A6: Oil (control) | B6: oil_brent_m1_usdbbl | C6: ICE Brent front-month (LSEG LCOc1) | D6: USD/bbl | E6: Oct 2014 - | F6: Main confounder: Hormuz hits oil and gas together, and inflation swaps are historically oil-driven. | G6: WTI (US benchmark, less relevant for Europe). | H6: Roll days removed.
A7: FX (control) | B7: fx_eurusd | C7: EUR/USD spot (LSEG EUR=) | D7: USD per EUR | E7: Oct 2014 - | F7: Energy is priced in USD; EUR moves change the euro cost of oil and risk sentiment. | G7: - | H7: Mid of bid/ask.
A8: Inflation expectations (near) | B8: ils_eur_1y | C8: EUR 1Y zero-coupon inflation swap, HICPxT (LSEG/Tradeweb EUCPIZ1Y=TWEB) | D8: % | E8: Apr 2022 - | F8: Captures expected inflation over the next year: where gas pass-through shows up first. | G8: HICP flash surveys (monthly, not market-based). | H8: Short history (from 2022).
A9: Inflation expectations (forward) | B9: ils_eur_1y1y | C9: EUR inflation swap 1y forward 1y (LSEG EUIL1YF1Y=R) | D9: % | E9: Jan 2016 - | F9: Inflation 1-2 years ahead = the ECB's policy horizon; strips out the mechanical near-term carry. | G9: 5y5y (long-run anchoring - not available, suggested addition). | H9: File was mislabelled '1Y'; renamed.
A10: Rate-hike expectations | B10: ois_estr_1y1y / ois_estr_2y | C10: €STR OIS 1M, 3M, 1Y, 2Y (LSEG EUREST*=); 1y1y derived | D10: % | E10: Sep 2019 - | F10: OIS is the cleanest market measure of the expected ECB path: no credit, scarcity or collateral premium (unlike Bunds). 1y1y = expected rate one year ahead. | G10: Euribor futures (contain bank credit premium), ECB-dated OIS (not available). | H10: Mid of bid/ask.
A11: Bund curve | B11: bund_2y ... bund_30y | C11: Bundesbank daily yields of current federal securities (BBSSY) | D11: % | E11: 2Y/5Y/10Y/30Y from 2014; 7Y/15Y from 2020; 20Y from Jan 2026 | F11: Official, free, long history. 2Y Schatz = policy-sensitive end; 30Y = term premium / long-run end. | G11: Zero-coupon fitted curve (would remove on-the-run roll effects - suggested robustness). | H11: Snapshot taken ~half a day before LSEG closes: timing-adjusted.
A12: Curve shape | B12: slope_2s10s, slope_2s30s, slope_5s30s, fly_2s5s10s, PCA | C12: Derived from Bund yields | D12: bp | E12: - | F12: Tests the 'specific moves' part of the thesis: policy shocks flatten, term-premium shocks steepen. | G12: - | H12: -
A13: Safety / scarcity premia | B13: swapsprd_de5y_bp, sprd_bund2y_ois2y | C13: 5Y IRS - Bund (LSEG DE5IRS5Y=RR); Bund 2Y - OIS 2Y | D13: bp | E13: 2014 - / 2019 - | F13: Separates genuine policy repricing from flight-to-quality into Bunds. | G13: - | H13: -
A14: Realised inflation | B14: hicp_ea_idx / _yoy / _mom | C14: Euro-area HICP index (2025=100) | D14: index / % | E14: Dec 1999 - | F14: First link of the chain at its natural (monthly) frequency. | G14: HICP energy sub-index (suggested addition). | H14: Base-splice break removed; NSA - month dummies used.
A15: Robustness only | B15: gas_nbp_m1_*, gas_hh_m1_usdmmbtu, gas_eu_imf_usdmmbtu_mavg | C15: NBP, Henry Hub, IMF EU gas | D15: various | E15: various | F15: Cross-checks; HH is the US leg of the LNG arbitrage. | G15: - | H15: Not used in headline tests.

Sheet Test_Catalog
A1: Catalog of econometric tests: what each answers, result, and economic meaning
A2: Ordered from data properties to identification to predictivity. 'Sheet' points to the full table.
A4: Category | B4: Test | C4: Question | D4: Null hypothesis (H0) | E4: Result | F4: Economic meaning / consequence | G4: Sheet
A5: Data properties | B5: Jarque-Bera | C5: Are daily changes normal? | D5: Normality | E5: Rejected for all series (excess kurtosis up to 15). | F5: Fat tails -> rely on robust (HAC) inference and bootstrap CIs. | G5: Descriptive
A6: Data properties | B6: Ljung-Box Q(10) | C6: Are changes autocorrelated? | D6: No autocorrelation | E6: Rejected in the full sample for 2Y Bund, TTF, ILS; not in the war regime. | F6: Mild serial dependence -> Newey-West SEs. | G6: Descriptive
A7: Data properties | B7: ARCH-LM(5) | C7: Volatility clustering? | D7: No ARCH | E7: Strongly rejected in full sample. | F7: Volatility regimes -> HAC SEs; regime split. | G7: Descriptive
A8: Stationarity | B8: ADF / KPSS / Zivot-Andrews | C8: Levels or changes? | D8: Unit root (ADF, ZA) / stationary (KPSS) | E8: All levels I(1); all changes I(0) (OIS 2Y borderline on ADF only). | F8: Regressions in levels would be spurious -> model changes. | G8: Unit_Roots
A9: Long-run relation | B9: Engle-Granger, Johansen | C9: Do gas and yields share a long-run equilibrium? | D9: No cointegration | E9: No pairwise cointegration; Johansen rank > 0 is likely break-driven (2022). | F9: No stable levels relationship: gas is a shock driver, not an anchor for yields. | G9: Cointegration
A10: Transmission | B10: OLS with Newey-West HAC, by regime | C10: How much do rates move per gas move? | D10: beta = 0 | E10: War: ILS 1Y, OIS, Bund 2Y, 2s30s significant; 2021-22 negative; normal times ~0. | F10: Core result: gas is a front-end policy driver in the war. | G10: Transmission_Daily / _Weekly
A11: Multiple testing | B11: Holm correction | C11: Are results artefacts of testing many series? | D11: All betas = 0 | E11: War regime: ILS 1Y survives across all 20 series (p = 0.005); Bund 2Y survives within the rates family (p = 0.036), borderline across all 20 (p = 0.057); 2s5s survives within the curve-shape family (p = 0.045). | F11: The headline is not a data-mining artefact, but individual slope results are suggestive. | G11: Transmission_Daily
A12: Regime | B12: Interaction Wald test | C12: Is the war beta different from normal? | D12: Equal betas | E12: Rejected for Bund 2Y, ILS 1Y, 2s10s, 2s30s. | F12: The link is regime-specific. | G12: Regime_Tests
A13: Regime | B13: Chow, HAC Wald, Quandt-Andrews sup-Wald | C13: Is there a break, and when? | D13: No break | E13: OIS 1y1y / OIS 2Y: break dated 5-11 Mar 2026 (1%). Slopes: break in Feb-Mar 2025 (German fiscal shock). | F13: The data locate the regime change at the war onset on their own. | G13: Structural_Breaks
A14: Regime | B14: CUSUM | C14: Are full-sample coefficients stable? | D14: Stable | E14: Rejected for Bund levels in the full sample. | F14: A single full-sample beta is misleading. | G14: Diagnostics
A15: Residuals | B15: Durbin-Watson, Breusch-Godfrey, Ljung-Box | C15: Serial correlation in residuals? | D15: None | E15: Present in the full sample; in the war regime only for OIS 1y1y and Bund 10Y. | F15: Handled by HAC SEs. | G15: Diagnostics
... A27: Events | B27: Event study | C27: What happened on key dates? | D27: - | E27: War onset (2-day): Bund 2Y +16bp vs 30Y +6bp, 2s10s -5bp. Ceasefire: OIS 1y1y -23bp, 2s10s +7bp (reversal). | F27: Narrative check of the regressions. | G27: Event_Study

Sheet Charts
A1: Charts
A2: Rendered by src/figures.py; PNGs in output/figures/.

Sheet Descriptive
A1: Descriptive statistics of daily changes
A2: Rates in bp/day, prices in %/day (log). Jarque-Bera: H0 normal. Ljung-Box Q(10): H0 no autocorrelation. ARCH-LM(5): H0 no volatility clustering.
A3: Source: src/econometrics.py -> output/tables/01_descriptive_stats.csv. Green cells: p < 0.05.
A5: regime | B5: series | C5: n | D5: mean | E5: std | F5: skew | G5: excess_kurtosis | H5: min | I5: max | J5: acf_lag1 | K5: jarque_bera_p | L5: ljung_box_q10_p | M5: arch_lm5_p
A6: Full sample | B6: r_gas_ttf_m1_eurmwh | C6: 2906 | D6: -0.030016373 | E6: 4.3519598 | F6: 0.30857923 | G6: 10.83094 | H6: -35.242114 | I6: 41.278433 | J6: 0.019944491 | K6: 0 | L6: 1.5037619e-06 | M6: 2.5007293e-142
A7: Full sample | B7: r_oil_brent_m1_usdbbl | C7: 2914 | D7: 0.041326891 | E7: 2.5486162 | F7: -0.88532521 | G7: 13.936819 | H7: -27.97615 | I7: 19.077401 | J7: 0.013252685 | K7: 0 | L7: 0.030529305 | M7: 2.4827544e-32
A8: Full sample | B8: d_ils_eur_1y1y | C8: 2733 | D8: 0.051061105 | E8: 3.7313329 | F8: -0.57170816 | G8: 9.1537539 | H8: -33.58 | I8: 23.45 | J8: 0.0724852 | K8: 0 | L8: 1.221248e-05 | M8: 1.5689689e-56
A9: Full sample | B9: d_ois_estr_1y1y | C9: 1784 | D9: 0.22201512 | E9: 6.0815181 | F9: -0.28275193 | G9: 4.3915885 | H9: -34.526408 | I9: 31.808072 | J9: 0.020130158 | K9: 0 | L9: 0.083434088 | M9: 6.2055224e-59
A10: Full sample | B10: d_bund_2y | C10: 3041 | D10: 0.10358435 | E10: 4.1229609 | F10: -0.5490209 | G10: 15.253767 | H10: -43 | I10: 34 | J10: -0.031378925 | K10: 0 | L10: 1.4500629e-05 | M10: 1.510814e-98
A11: Full sample | B11: d_bund_10y | C11: 3041 | D11: 0.084840513 | E11: 4.5188243 | F11: -0.022796307 | G11: 4.4650005 | H11: -31 | I11: 28 | J11: -0.0072682594 | K11: 0 | L11: 0.30471559 | M11: 4.033675e-60
A12: Full sample | B12: d_bund_30y | C12: 3041 | D12: 0.066425518 | E12: 4.6088652 | F12: 0.03477846 | G12: 3.3762837 | H12: -26 | I12: 31 | J12: -0.0019643043 | K12: 0 | L12: 0.17490738 | M12: 9.5804082e-70
A13: Full sample | B13: d_slope_2s10s | C13: 3041 | D13: -0.018743834 | E13: 3.0126887 | F13: 0.39417249 | G13: 4.4104344 | H13: -17 | I13: 22 | J13: -0.030195186 | K13: 0 | L13: 0.43272527 | M13: 5.5086123e-54
A14: 2014-21 pre-crisis | B14: r_gas_ttf_m1_eurmwh | C14: 1620 | D14: -0.080463233 | E14: 2.8783339 | F14: 0.089310924 | G14: 6.9123277 | H14: -19.598744 | I14: 20.921308 | J14: 0.034258184 | K14: 0 | L14: 3.6595874e-05 | M14: 8.2947044e-55
A15: 2014-21 pre-crisis | B15: r_oil_brent_m1_usdbbl | C15: 1626 | D15: 0.0057718796 | E15: 2.6723812 | F15: -0.9459228 | G15: 18.399381 | H15: -27.97615 | I15: 19.077401 | J15: 0.012143548 | K15: 0 | L15: 0.19840389 | M15: 4.5524093e-18
A16: 2014-21 pre-crisis | B16: d_ils_eur_1y1y | C16: 1387 | D16: 0.02777938 | E16: 2.4164677 | F16: -0.72583427 | G16: 7.7801421 | H16: -18.12 | I16: 15.86 | J16: 0.077174811 | K16: 0 | L16: 0.00058393166 | M16: 3.1282384e-14
A17: 2014-21 pre-crisis | B17: d_ois_estr_1y1y | C17: 438 | D17: 0.047529175 | E17: 1.6441371 | F17: 0.18548711 | G17: 2.6682798 | H17: -6.4998582 | I17: 7.3402073 | J17: -0.013329702 | K17: 1.7362879e-29 | L17: 0.00020981615 | M17: 5.428318e-15
... A45: Iran war (Mar 2026+) | B45: d_slope_2s10s | C45: 157 | D45: -0.17834395 | E45: 2.8159418 | F45: 0.073937679 | G45: 1.4694366 | H45: -9 | I45: 10 | J45: -0.07404954 | K45: 0.00079748265 | L45: 0.82323267 | M45: 0.0019107777

Sheet Unit_Roots
A1: Stationarity: ADF, KPSS and Zivot-Andrews (weekly levels & changes)
A2: ADF / Zivot-Andrews H0: unit root. KPSS H0: stationary. 'stationary' = ADF rejects and KPSS does not. Zivot-Andrews allows one endogenous break (break date reported).
A3: Source: src/econometrics.py -> output/tables/02_unit_roots.csv. Green cells: p < 0.05.
A5: series | B5: form | C5: n_weeks | D5: adf_stat | E5: adf_p | F5: kpss_stat | G5: kpss_p | H5: za_stat | I5: za_p | J5: za_break_date | K5: verdict
A6: bund_2y | B6: level | C6: 626 | D6: 0.23646385 | E6: 0.97423416 | F6: 2.6936867 | G6: 0.01 | H6: -5.7517788 | I6: 0.0015323937 | J6: 2022-03-04 | K6: unit root
A7: bund_2y | B7: first difference | C7: 625 | D7: -9.8966206 | E7: 3.4443487e-17 | F7: 0.38921357 | G7: 0.081804494 | H7: -10.916834 | I7: 1e-05 | J7: 2023-03-03 | K7: stationary
A8: bund_10y | B8: level | C8: 626 | D8: 0.39908966 | E8: 0.98146087 | F8: 2.4198054 | G8: 0.01 | H8: -4.6791971 | I8: 0.074471909 | J8: 2022-03-04 | K8: unit root
A9: bund_10y | B9: first difference | C9: 625 | D9: -10.472184 | E9: 1.2758537e-18 | F9: 0.41451192 | G9: 0.070900033 | H9: -11.043947 | I9: 1e-05 | J9: 2023-03-03 | K9: stationary
A10: bund_30y | B10: level | C10: 626 | D10: -0.071916588 | E10: 0.9521649 | F10: 2.0626869 | G10: 0.01 | H10: -3.8290202 | I10: 0.46012255 | J10: 2022-03-04 | K10: unit root
A11: bund_30y | B11: first difference | C11: 625 | D11: -24.033485 | E11: 0 | F11: 0.42506437 | G11: 0.066351563 | H11: -10.772353 | I11: 1e-05 | J11: 2023-10-27 | K11: stationary
A12: slope_2s10s | B12: level | C12: 626 | D12: -1.7573482 | E12: 0.40183314 | F12: 1.5817503 | G12: 0.01 | H12: -3.3267329 | I12: 0.7810992 | J12: 2024-07-19 | K12: unit root
A13: slope_2s10s | B13: first difference | C13: 625 | D13: -18.845901 | E13: 0 | F13: 0.087628756 | G13: 0.1 | H13: -19.126035 | I13: 1e-05 | J13: 2023-06-30 | K13: stationary
A14: ln_ttf | B14: level | C14: 626 | D14: -1.78718 | E14: 0.38684478 | F14: 1.4994769 | G14: 0.01 | H14: -4.0738235 | I14: 0.30728428 | J14: 2021-03-19 | K14: unit root
A15: ln_ttf | B15: first difference | C15: 625 | D15: -6.1704572 | E15: 6.8253416e-08 | F15: 0.10696912 | G15: 0.1 | H15: -7.178263 | I15: 1e-05 | J15: 2022-08-26 | K15: stationary
A16: ln_brent | B16: level | C16: 626 | D16: -2.3215791 | E16: 0.16510271 | F16: 1.5612514 | G16: 0.01 | H16: -4.1626944 | I16: 0.25824997 | J16: 2020-10-30 | K16: unit root
A17: ln_brent | B17: first difference | C17: 625 | D17: -18.118134 | E17: 2.5261262e-30 | F17: 0.10370991 | G17: 0.1 | H17: -18.394453 | I17: 1e-05 | J17: 2020-04-24 | K17: stationary
... A25: swapsprd_de5y_bp | B25: first difference | C25: 625 | D25: -13.742082 | E25: 1.0896206e-25 | F25: 0.11293644 | G25: 0.1 | H25: -14.406208 | I25: 1e-05 | J25: 2022-10-14 | K25: stationary

Sheet Cointegration
A1: Cointegration: Engle-Granger (pairs) and Johansen (systems)
A2: H0 (EG): no cointegration. Johansen: sequential trace test at 5%. Weekly levels.
A3: Source: src/econometrics.py -> output/tables/03_cointegration.csv. Green cells: p < 0.05.
A5: test | B5: system | C5: n_weeks | D5: stat | E5: p_value | F5: rank_at_5pct | G5: verdict
A6: Engle-Granger | B6: bund_2y ~ ln_ttf | C6: 627 | D6: -1.1679487 | E6: 0.86609493 | F6: 0 | G6: no cointegration
A7: Engle-Granger | B7: ils_eur_1y1y ~ ln_ttf | C7: 562 | D7: -2.4043636 | E7: 0.32279107 | F7: 0 | G7: no cointegration
A8: Engle-Granger | B8: ils_eur_1y1y ~ ln_brent | C8: 562 | D8: -3.3090603 | E8: 0.05350274 | F8: 0 | G8: no cointegration
A9: Engle-Granger | B9: ois_estr_1y1y ~ ils_eur_1y1y | C9: 367 | D9: -1.3472284 | E9: 0.81502904 | F9: 0 | G9: no cointegration
A10: Engle-Granger | B10: bund_2y ~ ois_estr_2y | C10: 368 | D10: -1.097212 | E10: 0.88280525 | F10: 0 | G10: no cointegration
A11: Engle-Granger | B11: bund_2y ~ ils_eur_1y1y | C11: 562 | D11: -1.9269605 | E11: 0.56627291 | F11: 0 | G11: no cointegration
A12: Johansen trace | B12: bund_2y , ils_eur_1y1y , ln_ttf , ln_brent | C12: 562 | D12: 64.54914 | F12: 3 | G12: rank 3 (trace r=0: 64.5 vs 5% cv 47.9)
A13: Johansen trace | B13: bund_2y , ois_estr_1y1y , ils_eur_1y1y , ln_ttf | C13: 367 | D13: 56.576462 | F13: 1 | G13: rank 1 (trace r=0: 56.6 vs 5% cv 47.9)

Sheet Transmission_Daily
A1: Transmission regressions, daily: change in rate on TTF, Brent, EURUSD - by regime
A2: bp_per_10pct_ttf = total effect of a +10% TTF move in bp (same day + previous day for Bundesbank yields, which are snapshotted before the market close). Newey-West HAC SEs.
A3: Multiple testing (Holm, within each regime): p_ttf_holm = across all 20 dependent variables (strictest); p_ttf_holm_family = within its family (rates & spreads: 13 series; curve shape: 7 series).
A4: Source: src/econometrics.py -> output/tables/04_transmission_daily.csv. Green cells: p < 0.05.
A6: dependent | B6: family | C6: regime | D6: n | E6: async_adjusted | F6: bp_per_10pct_ttf | G6: t_ttf | H6: p_ttf | I6: p_ttf_holm | J6: p_ttf_holm_family | K6: beta_ttf_same_day | L6: beta_ttf_prev_day | M6: bp_per_10pct_brent | N6: t_brent | O6: p_brent | P6: r2
A7: Infl. swap 1Y | B7: rates & spreads | C7: 2021-22 gas crisis | D7: 169 | E7: FALSE | F7: 6.4891979 | G7: 2.9221611 | H7: 0.0034761174 | I7: 0.069522348 | J7: 0.045189526 | K7: 0.68085045 | M7: 17.380099 | N7: 3.1836971 | O7: 0.001454071 | P7: 0.20154335
A8: Infl. swap 1Y | B8: rates & spreads | C8: 2023-Feb26 normalisation | D8: 735 | E8: FALSE | F8: 1.5550916 | G8: 3.2896547 | H8: 0.0010031038 | I8: 0.019058972 | J8: 0.012037246 | K8: 0.16316113 | M8: 12.48597 | N8: 8.4868453 | O8: 2.1232206e-17 | P8: 0.2229971
A9: Infl. swap 1Y | B9: rates & spreads | C9: Iran war (Mar 2026+) | D9: 142 | E9: FALSE | F9: 6.8789576 | G9: 3.6801715 | H9: 0.00023307715 | I9: 0.004661543 | J9: 0.0030300029 | K9: 0.72174427 | M9: 17.393151 | N9: 10.65773 | O9: 1.6046576e-26 | P9: 0.6724957
A10: Infl. swap 1Y | B10: rates & spreads | C10: Full sample | D10: 1046 | E10: FALSE | F10: 3.8547641 | G10: 4.6379116 | H10: 3.519473e-06 | I10: 7.0389459e-05 | J10: 4.5753149e-05 | K10: 0.40444411 | M10: 15.35564 | N10: 13.215344 | O10: 7.1558049e-40 | P10: 0.29104635
A11: Infl. swap 1y1y | B11: rates & spreads | C11: 2014-21 pre-crisis | D11: 1271 | E11: FALSE | F11: 0.34640216 | G11: 1.8672121 | H11: 0.061871969 | I11: 0.72486258 | J11: 0.56316347 | K11: 0.036344717 | M11: 3.4070986 | N11: 6.9923419 | O11: 2.7033501e-12 | P11: 0.19489918
A12: Infl. swap 1y1y | B12: rates & spreads | C12: 2021-22 gas crisis | D12: 352 | E12: FALSE | F12: 1.5628497 | G12: 2.7745418 | H12: 0.0055279532 | I12: 0.10503111 | J12: 0.066335438 | K12: 0.16397511 | M12: 8.5477774 | N12: 5.5761918 | O12: 2.4584086e-08 | P12: 0.22689919
A13: Infl. swap 1y1y | B13: rates & spreads | C13: 2023-Feb26 normalisation | D13: 735 | E13: FALSE | F13: 1.0641887 | G13: 3.8137744 | H13: 0.00013686041 | I13: 0.0027372082 | J13: 0.0017791854 | K13: 0.1116553 | M13: 7.240404 | N13: 8.3950103 | O13: 4.6585337e-17 | P13: 0.214967
A14: Infl. swap 1y1y | B14: rates & spreads | C14: Iran war (Mar 2026+) | D14: 143 | E14: FALSE | F14: 1.7705902 | G14: 2.2740406 | H14: 0.022963549 | I14: 0.34445323 | J14: 0.25259903 | K14: 0.18577136 | M14: 4.9141169 | N14: 6.9975301 | O14: 2.6051407e-12 | P14: 0.42468057
A15: Infl. swap 1y1y | B15: rates & spreads | C15: Full sample | D15: 2501 | E15: FALSE | F15: 1.2896689 | G15: 3.5176062 | H15: 0.00043545812 | I15: 0.0082737043 | J15: 0.0052254974 | K15: 0.13531282 | M15: 4.9165004 | N15: 10.531256 | O15: 6.2001581e-26 | P15: 0.19898585
A16: €STR OIS 1Y | B16: rates & spreads | C16: 2014-21 pre-crisis | D16: 403 | E16: FALSE | F16: 0.036903478 | G16: 0.47872392 | H16: 0.63213504 | I16: 1 | J16: 1 | K16: 0.0038719346 | M16: 0.36998707 | N16: 1.1988237 | O16: 0.2305965 | P16: 0.046907894
A17: €STR OIS 1Y | B17: rates & spreads | C17: 2021-22 gas crisis | D17: 352 | E17: FALSE | F17: -0.42744555 | G17: -1.7346281 | H17: 0.082806707 | I17: 0.95091246 | J17: 0.44706576 | K17: -0.044847837 | M17: 2.1082221 | N17: 2.0335972 | O17: 0.041992222 | P17: 0.020077917
A18: €STR OIS 1Y | B18: rates & spreads | C18: 2023-Feb26 normalisation | D18: 735 | E18: FALSE | F18: 0.13435143 | G18: 0.40331071 | H18: 0.68671966 | I18: 1 | J18: 1 | K18: 0.014096231 | M18: 3.4547174 | N18: 3.0700631 | O18: 0.0021401356 | P18: 0.032510444
... A30: €STR OIS 2Y | B30: rates & spreads | C30: Full sample | D30: 1634 | E30: FALSE | F30: 0.14368548 | G30: 0.50730145 | H30: 0.61194332 | I30: 1 | J30: 1 | K30: 0.015075565 | M30: 3.5772975 | N30: 4.7119295 | O30: 2.4538222e-06 | P30: 0.053006524
A31: Bund 2Y | B31: rates & spreads | C31: 2014-21 pre-crisis | D31: 1473 | E31: TRUE | F31: 0.31087629 | G31: 1.5931991 | H31: 0.11111553 | I31: 1 | J31: 0.88892422 | K31: 0.0059823954 | L31: 0.026634927 | M31: 0.62133206 | N31: 1.5490442 | O31: 0.12137109 | P31: 0.02394434
A32: Bund 2Y | B32: rates & spreads | C32: 2021-22 gas crisis | D32: 335 | E32: TRUE | F32: -1.2393012 | G32: -2.224082 | H32: 0.026142926 | I32: 0.44442975 | J32: 0.26142926 | K32: -0.1224204 | L32: -0.007607804 | M32: 4.4054262 | N32: 2.4407122 | O32: 0.01465833 | P32: 0.035779889
A33: Bund 2Y | B33: rates & spreads | C33: 2023-Feb26 normalisation | D33: 699 | E33: TRUE | F33: -0.33541895 | G33: -0.31066848 | H33: 0.75605266 | I33: 1 | J33: 1 | K33: 0.061522628 | L33: -0.096714981 | M33: 7.3896377 | N33: 3.7844741 | O33: 0.00015403397 | P33: 0.046769145
A34: Bund 2Y | B34: rates & spreads | C34: Iran war (Mar 2026+) | D34: 135 | E34: TRUE | F34: 4.0791826 | G34: 2.970368 | H34: 0.0029744321 | I34: 0.056514211 | J34: 0.035693186 | K34: 0.40410906 | L34: 0.023881176 | M34: 5.7569207 | N34: 5.2029907 | O34: 1.9610669e-07 | P34: 0.39710496
A35: Bund 2Y | B35: rates & spreads | C35: Full sample | D35: 2642 | E35: TRUE | F35: -0.18862415 | G35: -0.48580209 | H35: 0.62710749 | I35: 1 | J35: 1 | K35: -0.0013306519 | L35: -0.018459905 | M35: 3.2251624 | N35: 5.3083142 | O35: 1.1064379e-07 | P35: 0.02279815
A36: Bund 5Y | B36: rates & spreads | C36: 2014-21 pre-crisis | D36: 1473 | E36: TRUE | F36: 0.53441222 | G36: 1.9085796 | H36: 0.056316347 | I36: 0.72486258 | J36: 0.56316347 | K36: 0.020879383 | L36: 0.035191461 | M36: 0.81586839 | N36: 1.361722 | O36: 0.17328564 | P36: 0.025207525
A37: Bund 5Y | B37: rates & spreads | C37: 2021-22 gas crisis | D37: 335 | E37: TRUE | F37: -1.3523229 | G37: -2.0165117 | H37: 0.043746493 | I37: 0.6561974 | J37: 0.34997194 | K37: -0.11974135 | L37: -0.022145163 | M37: 5.6812094 | N37: 2.8580739 | O37: 0.0042622115 | P37: 0.046023531
A38: Bund 5Y | B38: rates & spreads | C38: 2023-Feb26 normalisation | D38: 699 | E38: TRUE | F38: -0.40194285 | G38: -0.3891089 | H38: 0.69719559 | I38: 1 | J38: 1 | K38: 0.047076642 | L38: -0.089248722 | M38: 7.867434 | N38: 4.1391104 | O38: 3.486551e-05 | P38: 0.060930803
A39: Bund 5Y | B39: rates & spreads | C39: Iran war (Mar 2026+) | D39: 135 | E39: TRUE | F39: 2.0104565 | G39: 1.6429324 | H39: 0.10039693 | I39: 0.80317543 | J39: 0.7027785 | K39: 0.24810054 | L39: -0.037162267 | M39: 5.9599347 | N39: 5.6754494 | O39: 1.3832502e-08 | P39: 0.37731504
A40: Bund 5Y | B40: rates & spreads | C40: Full sample | D40: 2642 | E40: TRUE | F40: -0.17988582 | G40: -0.43005661 | H40: 0.66715446 | I40: 1 | J40: 1 | K40: -0.0045542794 | L40: -0.014319446 | M40: 3.3990607 | N40: 5.0517205 | O40: 4.3784808e-07 | P40: 0.023613972
A41: Bund 7Y | B41: rates & spreads | C41: 2014-21 pre-crisis | D41: 251 | E41: TRUE | F41: 0.30503532 | G41: 0.64260365 | H41: 0.52048132 | I41: 1 | J41: 1 | K41: 0.02630177 | L41: 0.0057027146 | M41: 2.9729382 | N41: 2.2798591 | O41: 0.022616047 | P41: 0.064572937
A42: Bund 7Y | B42: rates & spreads | C42: 2021-22 gas crisis | D42: 335 | E42: TRUE | F42: -1.4623426 | G42: -2.3002024 | H42: 0.021436756 | I42: 0.3858616 | J42: 0.23580431 | K42: -0.12940294 | L42: -0.024026906 | M42: 5.196393 | N42: 2.8769969 | O42: 0.0040147958 | P42: 0.051885051
... A95: Fly 2s5s10s | B95: curve shape | C95: Full sample | D95: 2642 | E95: TRUE | F95: 0.027361479 | G95: 0.1580628 | H95: 0.87440731 | I95: 1 | J95: 1 | K95: -0.0035822762 | L95: 0.0064530587 | M95: -0.090220629 | N95: -0.3127824 | O95: 0.75444599 | P95: 0.0055193743
A96: 5Y swap spread (IRS-Bund) | B96: rates & spreads | C96: 2014-21 pre-crisis | D96: 1552 | E96: FALSE | F96: 0.10402398 | G96: 1.0713724 | H96: 0.28400204 | I96: 1 | J96: 1 | K96: 0.010914257 | M96: -0.43771984 | N96: -1.8218581 | O96: 0.068476512 | P96: 0.017313736
A97: 5Y swap spread (IRS-Bund) | B97: rates & spreads | C97: 2021-22 gas crisis | D97: 352 | E97: FALSE | F97: 0.12254097 | G97: 0.89192056 | H97: 0.37243551 | I97: 1 | J97: 0.47422074 | K97: 0.01285707 | M97: -0.039501705 | N97: -0.086133469 | O97: 0.93136032 | P97: 0.062802814
A98: 5Y swap spread (IRS-Bund) | B98: rates & spreads | C98: 2023-Feb26 normalisation | D98: 699 | E98: FALSE | F98: 0.074129305 | G98: 0.43545346 | H98: 0.66323331 | I98: 1 | J98: 1 | K98: 0.0077776902 | M98: -0.91296432 | N98: -1.8465627 | O98: 0.064810546 | P98: 0.010475314
A99: 5Y swap spread (IRS-Bund) | B99: rates & spreads | C99: Iran war (Mar 2026+) | D99: 95 | E99: FALSE | F99: 1.3127012 | G99: 0.64453487 | H99: 0.51922865 | I99: 1 | J99: 1 | K99: 0.13772938 | M99: 4.7463289 | N99: 2.1703336 | O99: 0.029981586 | P99: 0.21295817
A100: 5Y swap spread (IRS-Bund) | B100: rates & spreads | C100: Full sample | D100: 2698 | E100: FALSE | F100: 0.25087804 | G100: 2.1540146 | H100: 0.031239025 | I100: 0.56230245 | J100: 0.34362928 | K100: 0.026322271 | M100: 0.054943156 | N100: 0.16914483 | O100: 0.86568273 | P100: 0.013777198
A101: Bund2Y - OIS2Y | B101: rates & spreads | C101: 2014-21 pre-crisis | D101: 385 | E101: TRUE | F101: -0.27038383 | G101: -0.95121198 | H101: 0.34149678 | I101: 1 | J101: 1 | K101: -0.03533237 | L101: 0.0069635395 | M101: 0.72273498 | N101: 1.9190923 | O101: 0.054972659 | P101: 0.060008892
A102: Bund2Y - OIS2Y | B102: rates & spreads | C102: 2021-22 gas crisis | D102: 335 | E102: TRUE | F102: 0.62119399 | G102: 1.1822403 | H102: 0.23711037 | I102: 1 | J102: 0.47422074 | K102: -0.021024147 | L102: 0.086200185 | M102: -0.15302282 | N102: -0.11174094 | O102: 0.91102882 | P102: 0.026927716
A103: Bund2Y - OIS2Y | B103: rates & spreads | C103: 2023-Feb26 normalisation | D103: 699 | E103: TRUE | F103: 0.17682881 | G103: 0.28198861 | H103: 0.77795225 | I103: 1 | J103: 1 | K103: 0.042826919 | L103: -0.024273936 | M103: 1.7058334 | N103: 1.2283185 | O103: 0.21932741 | P103: 0.018929027
A104: Bund2Y - OIS2Y | B104: rates & spreads | C104: Iran war (Mar 2026+) | D104: 135 | E104: TRUE | F104: -0.31642086 | G104: -0.1266001 | H104: 0.89925692 | I104: 1 | J104: 1 | K104: 0.082389759 | L104: -0.11558882 | M104: 0.40966178 | N104: 0.20869816 | O104: 0.83468388 | P104: 0.32470848
...

Sheet Transmission_Weekly
A1: Transmission regressions, weekly (Fri-Fri): robustness to data timing
A2: Gas/Brent weekly returns = sum of roll-cleaned daily returns. For Bundesbank yields the market window is lagged one business day (Fri-Thu).
A3: Source: src/econometrics.py -> output/tables/04_transmission_weekly.csv. Green cells: p < 0.05.
A5: dependent | B5: family | C5: regime | D5: n | E5: bp_per_10pct_ttf | F5: t_ttf | G5: p_ttf | H5: p_ttf_holm | I5: p_ttf_holm_family | J5: bp_per_10pct_brent | K5: t_brent | L5: p_brent | M5: r2
A6: Infl. swap 1Y | B6: rates & spreads | C6: 2021-22 gas crisis | D6: 38 | E6: 18.002657 | F6: 3.0308648 | G6: 0.002438544 | H6: 0.04877088 | I6: 0.031701072 | J6: 20.776113 | K6: 2.0849075 | L6: 0.037077698 | M6: 0.29872992
A7: Infl. swap 1Y | B7: rates & spreads | C7: 2023-Feb26 normalisation | D7: 162 | E7: 1.9709252 | F7: 1.073087 | G7: 0.28323209 | H7: 1 | I7: 1 | J7: 20.071524 | K7: 4.5893437 | L7: 4.4464178e-06 | M7: 0.16520292
A8: Infl. swap 1Y | B8: rates & spreads | C8: Iran war (Mar 2026+) | D8: 32 | E8: 4.0416809 | F8: 1.360002 | G8: 0.1738293 | H8: 0.68845635 | I8: 0.51634226 | J8: 27.7581 | K8: 5.6824795 | L8: 1.3275582e-08 | M8: 0.69467213
A9: Infl. swap 1Y | B9: rates & spreads | C9: Full sample | D9: 232 | E9: 8.8984465 | F9: 2.8164272 | G9: 0.0048561044 | H9: 0.097122088 | I9: 0.063129357 | J9: 18.095253 | K9: 6.3315358 | L9: 2.4273283e-10 | M9: 0.24302294
A10: Infl. swap 1y1y | B10: rates & spreads | C10: 2014-21 pre-crisis | D10: 282 | E10: 0.4311393 | F10: 1.2410343 | G10: 0.21459309 | H10: 1 | I10: 1 | J10: 4.001519 | K10: 4.3614599 | L10: 1.2919747e-05 | M10: 0.22584588
A11: Infl. swap 1y1y | B11: rates & spreads | C11: 2021-22 gas crisis | D11: 79 | E11: 0.065410016 | F11: 0.04661242 | G11: 0.96282213 | H11: 1 | I11: 1 | J11: 15.382026 | K11: 4.2184843 | L11: 2.4595008e-05 | M11: 0.26230618
A12: Infl. swap 1y1y | B12: rates & spreads | C12: 2023-Feb26 normalisation | D12: 162 | E12: 0.11173075 | F12: 0.1694752 | G12: 0.86542287 | H12: 1 | I12: 1 | J12: 7.6882207 | K12: 3.4152416 | L12: 0.00063725468 | M12: 0.18715388
A13: Infl. swap 1y1y | B13: rates & spreads | C13: Iran war (Mar 2026+) | D13: 32 | E13: 2.5697766 | F13: 3.2809471 | G13: 0.0010345916 | H13: 0.016553466 | I13: 0.011380508 | J13: 3.0534834 | K13: 1.8251575 | L13: 0.067977269 | M13: 0.46696087
A14: Infl. swap 1y1y | B14: rates & spreads | C14: Full sample | D14: 555 | E14: 0.64670365 | F14: 0.82654053 | G14: 0.40849754 | H14: 1 | I14: 1 | J14: 6.1946997 | K14: 5.4841551 | L14: 4.1545018e-08 | M14: 0.17311385
A15: €STR OIS 1Y | B15: rates & spreads | C15: 2014-21 pre-crisis | D15: 89 | E15: 0.19773701 | F15: 1.1842981 | G15: 0.23629506 | H15: 1 | I15: 1 | J15: 0.41983044 | K15: 1.1940006 | L15: 0.23247773 | M15: 0.095688795
A16: €STR OIS 1Y | B16: rates & spreads | C16: 2021-22 gas crisis | D16: 79 | E16: -1.7276137 | F16: -2.5876375 | G16: 0.0096636623 | H16: 0.1546186 | I16: 0.08697296 | J16: -0.36441499 | K16: -0.23918481 | L16: 0.81096228 | M16: 0.10727717
A17: €STR OIS 1Y | B17: rates & spreads | C17: 2023-Feb26 normalisation | D17: 162 | E17: -0.053387615 | F17: -0.066340826 | G17: 0.94710648 | H17: 1 | I17: 1 | J17: 6.4971652 | K17: 2.4105988 | L17: 0.015926356 | M17: 0.10639936
... A104: Bund2Y - OIS2Y | B104: rates & spreads | C104: Full sample | D104: 363 | E104: -0.394574 | F104: -1.2106741 | G104: 0.22602034 | H104: 1 | I104: 1 | J104: 0.78480171 | K104: 1.256809 | L104: 0.20882282 | M104: 0.013118101

Sheet Regime_Tests
A1: Is the gas effect different in the war and in 2021-22? Pooled model with regime interactions
A2: Base = 2014-21 + 2023-Feb26 combined. H0: regime total effect = base total effect (HAC Wald).
A3: Source: src/econometrics.py -> output/tables/05_regime_interaction.csv. Green cells: p < 0.05.
A5: dependent | B5: regime_vs_base | C5: base_bp_per_10pct | D5: regime_bp_per_10pct | E5: difference_bp_per_10pct | F5: wald_t | G5: wald_p | H5: n
A6: Infl. swap 1Y | B6: 2021-22 gas crisis | C6: 1.5550916 | D6: 6.4891979 | E6: 4.9341063 | F6: 2.1182538 | G6: 0.034153583 | H6: 1046
A7: Infl. swap 1Y | B7: Iran war (Mar 2026+) | C7: 1.5550916 | D7: 6.8789576 | E7: 5.323866 | F7: 2.7280272 | G7: 0.0063714361 | H7: 1046
A8: Infl. swap 1y1y | B8: 2021-22 gas crisis | C8: 0.82020397 | D8: 1.5628497 | E8: 0.74264577 | F8: 1.1870829 | G8: 0.23519494 | H8: 2501
A9: Infl. swap 1y1y | B9: Iran war (Mar 2026+) | C9: 0.82020397 | D9: 1.7705902 | E9: 0.95038619 | F9: 1.2783356 | G9: 0.20113111 | H9: 2501
A10: €STR OIS 1y1y | B10: 2021-22 gas crisis | C10: 0.52904765 | D10: -1.0438441 | E10: -1.5728917 | F10: -2.2251724 | G10: 0.026069664 | H10: 1633
A11: €STR OIS 1y1y | B11: Iran war (Mar 2026+) | C11: 0.52904765 | D11: 2.3244218 | E11: 1.7953742 | F11: 1.6973263 | G11: 0.089634988 | H11: 1633
A12: €STR OIS 2Y | B12: 2021-22 gas crisis | C12: 0.34562499 | D12: -0.73416191 | E12: -1.0797869 | F12: -2.1680189 | G12: 0.030157251 | H12: 1634
A13: €STR OIS 2Y | B13: Iran war (Mar 2026+) | C13: 0.34562499 | D13: 2.0709758 | E13: 1.7253508 | F13: 1.8974569 | G13: 0.057767662 | H13: 1634
A14: Bund 2Y | B14: 2021-22 gas crisis | C14: 0.15690936 | D14: -1.2393012 | E14: -1.3962105 | F14: -1.8742966 | G14: 0.060889553 | H14: 2642
A15: Bund 2Y | B15: Iran war (Mar 2026+) | C15: 0.15690936 | D15: 4.0791826 | E15: 3.9222733 | F15: 2.8708627 | G15: 0.0040935327 | H15: 2642
A16: Bund 10Y | B16: 2021-22 gas crisis | C16: 0.35447385 | D16: -1.3471922 | E16: -1.7016661 | F16: -2.1001534 | G16: 0.035715348 | H16: 2642
A17: Bund 10Y | B17: Iran war (Mar 2026+) | C17: 0.35447385 | D17: 1.3227823 | E17: 0.96830848 | F17: 0.67652021 | G17: 0.49871042 | H17: 2642
... A33: 5Y swap spread (IRS-Bund) | B33: Iran war (Mar 2026+) | C33: 0.079779451 | D33: 1.3127012 | E33: 1.2329218 | F33: 0.63447372 | G33: 0.52577171 | H33: 2698

Sheet Diagnostics
A1: Residual diagnostics of the transmission regressions
A2: Durbin-Watson (~2 = no AR(1)); Breusch-Godfrey(5) & Ljung-Box(10): H0 no serial correlation; Breusch-Pagan & White: H0 homoskedastic; ARCH-LM(5): H0 no ARCH; Jarque-Bera: H0 normal; Ramsey RESET: H0 correct functional form; CUSUM: H0 stable coefficients; VIF > 5 = collinearity.
A3: Here green = rejection of the null, i.e. a problem detected (handled by HAC SEs / regime split).
A4: Source: src/econometrics.py -> output/tables/06_residual_diagnostics.csv. Green cells: p < 0.05.
A6: dependent | B6: sample | C6: n | D6: durbin_watson | E6: breusch_godfrey_5_p | F6: ljung_box_10_p | G6: breusch_pagan_p | H6: white_p | I6: arch_lm5_p | J6: jarque_bera_p | K6: reset_p | L6: cusum_p | M6: vif_ttf | N6: vif_brent | O6: corr_ttf_brent | P6: issues | Q6: remedy
A7: Infl. swap 1y1y | B7: Full sample | C7: 2501 | D7: 1.8341726 | E7: 0.0001076238 | F7: 1.3909457e-05 | G7: 0.12639346 | H7: 4.1166325e-69 | I7: 3.1941727e-66 | J7: 0 | K7: 0.10489843 | L7: 0.62795883 | M7: 1.055632 | N7: 1.0460485 | O7: 0.20981278 | P7: serial correlation, heteroskedasticity, ARCH, fat tails | Q7: Newey-West HAC SEs (robust to heteroskedasticity + autocorrelation); regime split for instability
A8: Infl. swap 1y1y | B8: Iran war (Mar 2026+) | C8: 143 | D8: 2.1723596 | E8: 0.06988554 | F8: 0.24904422 | G8: 0.016119169 | H8: 0.00043165478 | I8: 1.5351804e-07 | J8: 0.0321906 | K8: 0.15946902 | L8: 0.30013876 | M8: 1.8385994 | N8: 1.9044599 | O8: 0.67430507 | P8: heteroskedasticity, ARCH, fat tails | Q8: Newey-West HAC SEs (robust to heteroskedasticity + autocorrelation); regime split for instability
A9: €STR OIS 1y1y | B9: Full sample | C9: 1633 | D9: 2.0081378 | E9: 0.7224065 | F9: 0.068896124 | G9: 2.4391544e-05 | H9: 9.9485594e-35 | I9: 1.2795937e-48 | J9: 1.3979885e-308 | K9: 0.0003992349 | L9: 0.2975679 | M9: 1.0624478 | N9: 1.0493442 | O9: 0.21626936 | P9: heteroskedasticity, ARCH, fat tails, functional form | Q9: Newey-West HAC SEs (robust to heteroskedasticity + autocorrelation); regime split for instability
A10: €STR OIS 1y1y | B10: Iran war (Mar 2026+) | C10: 143 | D10: 2.3449973 | E10: 0.00029746957 | F10: 3.9460899e-05 | G10: 0.12608637 | H10: 0.00081802313 | I10: 0.0086146213 | J10: 0.0084203698 | K10: 0.55453733 | L10: 0.99610294 | M10: 1.8385994 | N10: 1.9044599 | O10: 0.67430507 | P10: serial correlation, heteroskedasticity, ARCH, fat tails | Q10: Newey-West HAC SEs (robust to heteroskedasticity + autocorrelation); regime split for instability
A11: Bund 2Y | B11: Full sample | C11: 2642 | D11: 2.0952629 | E11: 1.387787e-05 | F11: 3.2928892e-08 | G11: 0.0050100705 | H11: 2.4115367e-12 | I11: 2.2591263e-86 | J11: 0 | K11: 0.010618373 | L11: 0.025139329 | M11: 1.0529718 | N11: 1.0408844 | O11: 0.19658266 | P11: serial correlation, heteroskedasticity, ARCH, fat tails, functional form, parameter instability | Q11: Newey-West HAC SEs (robust to heteroskedasticity + autocorrelation); regime split for instability
A12: Bund 2Y | B12: Iran war (Mar 2026+) | C12: 135 | D12: 2.1999446 | E12: 0.27722799 | F12: 0.068452334 | G12: 0.14507416 | H12: 3.1927521e-07 | I12: 7.9706134e-06 | J12: 1.1280403e-06 | K12: 0.033555829 | L12: 0.9192047 | M12: 2.3462491 | N12: 2.1651937 | O12: 0.68897168 | P12: heteroskedasticity, ARCH, fat tails, functional form | Q12: Newey-West HAC SEs (robust to heteroskedasticity + autocorrelation); regime split for instability
A13: Bund 10Y | B13: Full sample | C13: 2642 | D13: 2.0237471 | E13: 0.12670893 | F13: 0.31135935 | G13: 6.3865948e-05 | H13: 7.3745869e-38 | I13: 2.9595056e-46 | J13: 0 | K13: 0.00057279323 | L13: 0.020272724 | M13: 1.0529718 | N13: 1.0408844 | O13: 0.19658266 | P13: heteroskedasticity, ARCH, fat tails, functional form, parameter instability | Q13: Newey-West HAC SEs (robust to heteroskedasticity + autocorrelation); regime split for instability
A14: Bund 10Y | B14: Iran war (Mar 2026+) | C14: 135 | D14: 1.8977733 | E14: 0.078900903 | F14: 0.00560644 | G14: 0.30259033 | H14: 0.011331064 | I14: 0.29057717 | J14: 0.22369166 | K14: 0.72919219 | L14: 0.97780678 | M14: 2.3462491 | N14: 2.1651937 | O14: 0.68897168 | P14: serial correlation, heteroskedasticity | Q14: Newey-West HAC SEs (robust to heteroskedasticity + autocorrelation); regime split for instability
A15: Bund 30Y | B15: Full sample | C15: 2642 | D15: 2.0232395 | E15: 0.27667779 | F15: 0.49152103 | G15: 3.5022714e-05 | H15: 5.6128708e-41 | I15: 1.005359e-56 | J15: 0 | K15: 0.0014837484 | L15: 0.016226733 | M15: 1.0529718 | N15: 1.0408844 | O15: 0.19658266 | P15: heteroskedasticity, ARCH, fat tails, functional form, parameter instability | Q15: Newey-West HAC SEs (robust to heteroskedasticity + autocorrelation); regime split for instability
A16: Bund 30Y | B16: Iran war (Mar 2026+) | C16: 135 | D16: 1.7789923 | E16: 0.26309856 | F16: 0.055840839 | G16: 0.41860058 | H16: 0.64103598 | I16: 0.82154716 | J16: 0.87655869 | K16: 0.44511835 | L16: 0.98936875 | M16: 2.3462491 | N16: 2.1651937 | O16: 0.68897168 | P16: none | Q16: OLS SEs valid
A17: Slope 2s10s | B17: Full sample | C17: 2642 | D17: 2.0536599 | E17: 0.65017967 | F17: 0.080136357 | G17: 0.014731772 | H17: 5.8211794e-29 | I17: 3.9022712e-45 | J17: 0 | K17: 0.00016594805 | L17: 0.71886311 | M17: 1.0529718 | N17: 1.0408844 | O17: 0.19658266 | P17: heteroskedasticity, ARCH, fat tails, functional form | Q17: Newey-West HAC SEs (robust to heteroskedasticity + autocorrelation); regime split for instability
A18: Slope 2s10s | B18: Iran war (Mar 2026+) | C18: 135 | D18: 2.2404114 | E18: 0.27738341 | F18: 0.38028552 | G18: 0.022846003 | H18: 8.3444607e-07 | I18: 0.036629915 | J18: 0.015978965 | K18: 0.016402546 | L18: 0.72638902 | M18: 2.3462491 | N18: 2.1651937 | O18: 0.68897168 | P18: heteroskedasticity, ARCH, fat tails, functional form | Q18: Newey-West HAC SEs (robust to heteroskedasticity + autocorrelation); regime split for instability

Sheet Structural_Breaks
A1: Structural breaks in the gas sensitivity (2023 - 2026)
A2: Chow F at 2 Mar 2026 (all coefficients). Robust Wald: shift in the total TTF effect at the war date (HAC). Quandt-Andrews sup-Wald: break date unknown, 15% trimming; 5% critical value 8.68 (Andrews 1993).
A3: Source: src/econometrics.py -> output/tables/07_structural_breaks.csv. Green cells: p < 0.05.
A5: dependent | B5: sample | C5: n | D5: chow_F_at_2026_03_02 | E5: chow_p | F5: ttf_effect_shift_bp_per_10pct | G5: robust_wald_p | H5: sup_wald_stat | I5: sup_wald_break_date | J5: sup_wald_cv_5pct | K5: sup_wald_significance | L5: searchable_window
A6: Bund 2Y | B6: 2023-01-05 to 2026-10-09 | C6: 834 | D6: 1.6702483 | E6: 0.11287295 | F6: 3.7486853 | G6: 0.04144925 | H6: 4.4199698 | I6: 2026-02-09 | J6: 8.68 | K6: not significant | L6: 2023-07-27 to 2026-03-17
A7: Bund 10Y | B7: 2023-01-05 to 2026-10-09 | C7: 834 | D7: 0.55571189 | E7: 0.79206123 | F7: 0.76609727 | G7: 0.67084763 | H7: 2.5027314 | I7: 2024-10-23 | J7: 8.68 | K7: not significant | L7: 2023-07-27 to 2026-03-17
A8: Slope 2s5s | B8: 2023-01-05 to 2026-10-09 | C8: 834 | D8: 2.2269367 | E8: 0.030215596 | F8: -2.3345893 | G8: 0.0044887715 | H8: 9.8462825 | I8: 2025-01-20 | J8: 8.68 | K8: 5% | L8: 2023-07-27 to 2026-03-17
A9: Slope 2s10s | B9: 2023-01-05 to 2026-10-09 | C9: 834 | D9: 2.2456618 | E9: 0.028842763 | F9: -2.982588 | G9: 0.020709106 | H9: 11.015624 | I9: 2025-02-14 | J9: 8.68 | K9: 5% | L9: 2023-07-27 to 2026-03-17
A10: Slope 2s30s | B10: 2023-01-05 to 2026-10-09 | C10: 834 | D10: 3.5938994 | E10: 0.00080523903 | F10: -4.9625032 | G10: 0.0023750211 | H10: 9.8435557 | I10: 2025-03-19 | J10: 8.68 | K10: 5% | L10: 2023-07-27 to 2026-03-17
A11: Infl. swap 1y1y | B11: 2023-01-04 to 2026-10-09 | C11: 878 | D11: 1.3730629 | E11: 0.24138041 | F11: -0.19690287 | G11: 0.78840662 | H11: 1.5237994 | I11: 2025-05-14 | J11: 8.68 | K11: not significant | L11: 2023-07-26 to 2026-03-18
A12: €STR OIS 1y1y | B12: 2023-01-04 to 2026-10-09 | C12: 878 | D12: 7.0719458 | E12: 1.3255863e-05 | F12: 4.3133553 | G12: 0.00037058823 | H12: 14.607346 | I12: 2026-03-11 | J12: 8.68 | K12: 1% | L12: 2023-07-26 to 2026-03-18
A13: €STR OIS 2Y | B13: 2023-01-04 to 2026-10-09 | C13: 878 | D13: 8.2975638 | E13: 1.4354138e-06 | F13: 3.8224095 | G13: 0.0001891266 | H13: 16.089202 | I13: 2026-03-05 | J13: 8.68 | K13: 1% | L13: 2023-07-26 to 2026-03-18

Sheet Timing
A1: Data timing & lead/lag (Dimson) tests
A2: Rows 1-3: Bundesbank yields load equally on previous- and same-day LSEG OIS moves => yields are observed ~half a day earlier. Remaining rows: TTF at t-1, t, t+1.
A3: Source: src/econometrics.py -> output/tables/09_lead_lag_timing.csv. Green cells: p < 0.05.
A5: test | B5: dependent | C5: regressor | D5: sample | E5: n | F5: beta_t-1 | G5: p_t-1 | H5: beta_t | I5: p_t | J5: beta_t+1 | K5: p_t+1 | L5: r2 | M5: dimson_sum_bp_per_10pct | N5: dimson_sum_p | O5: xcorr_gas(t-3) | P5: xcorr_gas(t-2) | Q5: xcorr_gas(t-1) | R5: xcorr_gas(t+0) | S5: xcorr_gas(t+1) | T5: xcorr_gas(t+2) | U5: xcorr_gas(t+3)
A6: timing vs OIS 2Y (LSEG close) | B6: Bund 2Y | C6: €STR OIS 2Y | D6: Oct 2019 - Oct 2026 | E6: 1782 | F6: 0.5258603 | G6: 1.5289613e-55 | H6: 0.4910978 | I6: 1.8881268e-27 | J6: -0.0095893273 | K6: 0.7649011 | L6: 0.42706371
A7: timing vs OIS 2Y (LSEG close) | B7: Bund 10Y | C7: €STR OIS 2Y | D7: Oct 2019 - Oct 2026 | E7: 1782 | F7: 0.45040388 | G7: 1.2586461e-45 | H7: 0.39051107 | I7: 8.3324643e-26 | J7: -0.0097730862 | K7: 0.73213353 | L7: 0.3068451
A8: timing vs OIS 2Y (LSEG close) | B8: Infl. swap 1y1y | C8: €STR OIS 2Y | D8: Oct 2019 - Oct 2026 | E8: 1782 | F8: 0.0011367729 | G8: 0.96915921 | H8: 0.25201711 | I8: 9.3641895e-09 | J8: 0.020074746 | K8: 0.50019482 | L8: 0.073990116
A9: Dimson TTF lead/lag | B9: Bund 2Y | C9: TTF | D9: Full sample | E9: 2629 | F9: -0.00011685457 | G9: 0.99671555 | H9: 0.0038240822 | I9: 0.92256633 | J9: -0.06195575 | K9: 0.061362008 | L9: 0.013284833 | M9: -0.55516771 | N9: 0.25719147 | O9: -0.032211038 | P9: -0.037249207 | Q9: 0.006322004 | R9: 0.012280427 | S9: -0.067915262 | T9: 0.0031133076 | U9: -0.017356076
A10: Dimson TTF lead/lag | B10: Bund 2Y | C10: TTF | D10: Iran war (Mar 2026+) | E10: 134 | F10: 0.18799063 | G10: 0.0066025947 | H10: 0.47818563 | I10: 7.5378839e-06 | J10: -0.027304457 | K10: 0.77158451 | L10: 0.34577589 | M10: 6.0890986 | N10: 0.00014762659 | O10: 0.023363104 | P10: -0.032356398 | Q10: 0.19263045 | R10: 0.45660777 | S10: -0.11016843 | T10: -0.077397598 | U10: -0.070860437
A11: Dimson TTF lead/lag | B11: Bund 10Y | C11: TTF | D11: Full sample | E11: 2629 | F11: 0.0037311749 | G11: 0.88427578 | H11: -0.0013298763 | I11: 0.97377164 | J11: -0.052576306 | K11: 0.085348075 | L11: 0.012663545 | M11: -0.4782189 | N11: 0.35938162 | O11: -0.0063265592 | P11: -0.030580184 | Q11: 0.0038852831 | R11: 0.010142444 | S11: -0.054815408 | T11: -0.00083849098 | U11: -0.010730268
A12: Dimson TTF lead/lag | B12: Bund 10Y | C12: TTF | D12: Iran war (Mar 2026+) | E12: 134 | F12: 0.14650117 | G12: 0.011479598 | H12: 0.33463645 | I12: 0.00013916418 | J12: 0.01800386 | K12: 0.81822533 | L12: 0.27007621 | M12: 4.7573264 | N12: 0.00013437831 | O12: 0.077062954 | P12: -0.07089838 | Q12: 0.19037149 | R12: 0.35816355 | S12: -0.077031085 | T12: -0.057807587 | U12: -0.06785788
A13: Dimson TTF lead/lag | B13: Infl. swap 1y1y | C13: TTF | D13: Full sample | E13: 2363 | F13: 0.018617843 | G13: 0.43400587 | H13: 0.12904765 | I13: 0.00012457336 | J13: -0.014878448 | K13: 0.43796052 | L13: 0.20171221 | M13: 1.2655957 | N13: 0.024146814 | O13: -0.0303003 | P13: -0.029557914 | Q13: 0.011554546 | R13: 0.23642622 | S13: 0.0055863015 | T13: -0.069120319 | U13: -0.028502996
A14: Dimson TTF lead/lag | B14: Infl. swap 1y1y | C14: TTF | D14: Iran war (Mar 2026+) | E14: 134 | F14: 0.0044329448 | G14: 0.91571249 | H14: 0.17754034 | I14: 0.037680451 | J14: 0.022245281 | K14: 0.84466732 | L14: 0.41403326 | M14: 1.9464108 | N14: 0.16174738 | O14: 0.16283133 | P14: -0.17913878 | Q14: -0.021190806 | R14: 0.50291562 | S14: 0.01241124 | T14: -0.12486278 | U14: -0.053387828
A15: Dimson TTF lead/lag | B15: €STR OIS 1y1y | C15: TTF | D15: Full sample | E15: 1544 | F15: -0.082853132 | G15: 0.0083351852 | H15: 0.028042891 | I15: 0.49098439 | J15: -0.063158951 | K15: 0.10641677 | L15: 0.057726567 | M15: -1.1243665 | N15: 0.072963393 | O15: 0.01569135 | P15: -0.005283398 | Q15: -0.052168291 | R15: 0.054839914 | S15: -0.04797179 | T15: -0.0046546966 | U15: -0.0095815243
A16: Dimson TTF lead/lag | B16: €STR OIS 1y1y | C16: TTF | D16: Iran war (Mar 2026+) | E16: 134 | F16: -0.11913019 | G16: 0.080001744 | H16: 0.23295871 | I16: 0.047005393 | J16: -0.014469783 | K16: 0.91275529 | L16: 0.59580228 | M16: 0.9469899 | N16: 0.58578381 | O16: 0.21749567 | P16: -0.071237536 | Q16: -0.089139137 | R16: 0.53132429 | S16: -0.019516609 | T16: 0.02973827 | U16: -0.14654517
A17: Dimson TTF lead/lag | B17: Slope 2s10s | C17: TTF | D17: Full sample | E17: 2629 | F17: 0.0038480295 | G17: 0.79092599 | H17: -0.0051539586 | I17: 0.75423912 | J17: 0.0093794438 | K17: 0.52049384 | L17: 0.0011725076 | M17: 0.076948813 | N17: 0.74104013 | O17: 0.034435118 | P17: 0.00542768 | Q17: -0.0028533457 | R17: -0.0014979418 | S17: 0.010903359 | T17: -0.0055030808 | U17: 0.0077090081
A18: Dimson TTF lead/lag | B18: Slope 2s10s | C18: TTF | D18: Iran war (Mar 2026+) | E18: 134 | F18: -0.041489463 | G18: 0.30454446 | H18: -0.14354917 | I18: 0.11052147 | J18: 0.045308316 | K18: 0.50601669 | L18: 0.11658289 | M18: -1.3317722 | N18: 0.31792324 | O18: 0.070806038 | P18: -0.040996616 | Q18: -0.07788894 | R18: -0.31692459 | S18: 0.091223145 | T18: 0.058555932 | U18: 0.031435197

Sheet Mediation
A1: Mediation: how much of the gas effect runs through inflation expectations and policy pricing?
A2: Daily rows: TTF -> inflation swap -> €STR OIS 1y1y (all LSEG closes, synchronous).
A3: Weekly rows: full serial chain TTF -> ILS 1y1y -> OIS 1y1y -> Bund 2Y. CIs: moving-block bootstrap, 2,000 draws.
A4: Effects in bp per 1% TTF (bp_per_10pct_ttf column x10%); path b / d21 coefficients in bp per bp.
A5: Source: src/econometrics.py -> output/tables/10_mediation.csv. Green cells: p < 0.05.
A7: frequency | B7: sample | C7: mediator | D7: n | E7: effect | F7: estimate | G7: ci95_lo | H7: ci95_hi | I7: significant_95 | J7: bp_per_10pct_ttf | K7: share_of_total
A8: daily | B8: Iran war (Mar 2026+) | C8: Infl. swap 1y1y | D8: 143 | E8: Total: TTF -> OIS 1y1y | F8: 0.2438797 | G8: 0.070075952 | H8: 0.47685659 | I8: TRUE | J8: 2.3244218 | K8: 1
